Workbook

Sheet Лист1
A1: 59.861 | AC1: Сдвиг ЧП | AD1: 1 | AE1: 2 | AF1: 3 | AG1: 4 | AH1: 5 | AI1: 6 | AJ1: 7 | AK1: 8 | AL1: 9 | AM1: 10
A2: 9.353 | AC2: К-т АК | AD2: =COVAR($A1:$A300,AD4:AD303)/SQRT(VAR($A1:$A300)*VAR(AD4:AD303)) -> 0.068572609 | AE2: =COVAR($A1:$A300,AE4:AE303)/SQRT(VAR($A1:$A300)*VAR(AE4:AE303)) -> -0.066529945 | AF2: =COVAR($A1:$A300,AF4:AF303)/SQRT(VAR($A1:$A300)*VAR(AF4:AF303)) -> -0.025656613 | AG2: =COVAR($A1:$A300,AG4:AG303)/SQRT(VAR($A1:$A300)*VAR(AG4:AG303)) -> 0.002051582 | AH2: =COVAR($A1:$A300,AH4:AH303)/SQRT(VAR($A1:$A300)*VAR(AH4:AH303)) -> -0.032502506 | AI2: =COVAR($A1:$A300,AI4:AI303)/SQRT(VAR($A1:$A300)*VAR(AI4:AI303)) -> 0.056598926 | AJ2: =COVAR($A1:$A300,AJ4:AJ303)/SQRT(VAR($A1:$A300)*VAR(AJ4:AJ303)) -> 0.055466317 | AK2: =COVAR($A1:$A300,AK4:AK303)/SQRT(VAR($A1:$A300)*VAR(AK4:AK303)) -> -0.074417429 | ... AM2: =COVAR($A1:$A300,AM4:AM303)/SQRT(VAR($A1:$A300)*VAR(AM4:AM303)) -> 0.023421996
A3: 4.713
A4: 4.612 | AD4: 9.353 | AE4: 4.713 | AF4: 4.612 | AG4: 6.48 | AH4: 7.944 | AI4: 5.281 | AJ4: 5.345 | AK4: 9.208 | AL4: 8.823 | AM4: 4.709
A5: 6.48 | AD5: 4.713 | AE5: 4.612 | AF5: 6.48 | AG5: 7.944 | AH5: 5.281 | AI5: 5.345 | AJ5: 9.208 | AK5: 8.823 | AL5: 4.709 | AM5: 4.723
A6: 7.944 | AD6: 4.612 | AE6: 6.48 | AF6: 7.944 | AG6: 5.281 | AH6: 5.345 | AI6: 9.208 | AJ6: 8.823 | AK6: 4.709 | AL6: 4.723 | AM6: 6.556
A7: 5.281 | AD7: 6.48 | AE7: 7.944 | AF7: 5.281 | AG7: 5.345 | AH7: 9.208 | AI7: 8.823 | AJ7: 4.709 | AK7: 4.723 | AL7: 6.556 | AM7: 58.414
A8: 5.345 | AD8: 7.944 | AE8: 5.281 | AF8: 5.345 | AG8: 9.208 | AH8: 8.823 | AI8: 4.709 | AJ8: 4.723 | AK8: 6.556 | AL8: 58.414 | AM8: 5.837
A9: 9.208 | AD9: 5.281 | AE9: 5.345 | AF9: 9.208 | AG9: 8.823 | AH9: 4.709 | AI9: 4.723 | AJ9: 6.556 | AK9: 58.414 | AL9: 5.837 | AM9: 25.02
A10: 8.823 | AD10: 5.345 | AE10: 9.208 | AF10: 8.823 | AG10: 4.709 | AH10: 4.723 | AI10: 6.556 | AJ10: 58.414 | AK10: 5.837 | AL10: 25.02 | AM10: 5.111
A11: 4.709 | AD11: 9.208 | AE11: 8.823 | AF11: 4.709 | AG11: 4.723 | AH11: 6.556 | AI11: 58.414 | AJ11: 5.837 | AK11: 25.02 | AL11: 5.111 | AM11: 7.895
A12: 4.723 | AD12: 8.823 | AE12: 4.709 | AF12: 4.723 | AG12: 6.556 | AH12: 58.414 | AI12: 5.837 | AJ12: 25.02 | AK12: 5.111 | AL12: 7.895 | AM12: 7.199
A13: 6.556 | AD13: 4.709 | AE13: 4.723 | AF13: 6.556 | AG13: 58.414 | AH13: 5.837 | AI13: 25.02 | AJ13: 5.111 | AK13: 7.895 | AL13: 7.199 | AM13: 4.613
A14: 58.414 | AD14: 4.723 | AE14: 6.556 | AF14: 58.414 | AG14: 5.837 | AH14: 25.02 | AI14: 5.111 | AJ14: 7.895 | AK14: 7.199 | AL14: 4.613 | AM14: 4.605
A15: 5.837 | AD15: 6.556 | AE15: 58.414 | AF15: 5.837 | AG15: 25.02 | AH15: 5.111 | AI15: 7.895 | AJ15: 7.199 | AK15: 4.613 | AL15: 4.605 | AM15: 9.218
... A20: 4.613 | AD20: 7.895 | AE20: 7.199 | AF20: 4.613 | AG20: 4.605 | AH20: 9.218 | AI20: 8.356 | AJ20: 7.548 | AK20: 4.927 | AL20: 5.52 | AM20: 5.226
A21: 4.605 | C21: Характеристика | E21: Количество случайных величин | AD21: 7.199 | AE21: 4.613 | AF21: 4.605 | AG21: 9.218 | AH21: 8.356 | AI21: 7.548 | AJ21: 4.927 | AK21: 5.52 | AL21: 5.226 | AM21: 5.172
A22: 9.218 | E22: 10 | F22: 20 | G22: 50 | H22: 100 | I22: 200 | J22: 300 | AD22: 4.613 | AE22: 4.605 | AF22: 9.218 | AG22: 8.356 | AH22: 7.548 | AI22: 4.927 | AJ22: 5.52 | AK22: 5.226 | AL22: 5.172 | AM22: 9.046
A23: 8.356 | C23: Мат. ож. | D23: Знач, | E23: =AVERAGE(A1:A10) -> 12.162 | F23: =AVERAGE(A1:A20) -> 12.58485 | G23: =AVERAGE(A1:A50) -> 13.95694 | H23: =AVERAGE(A1:A100) -> 16.73098 | I23: =AVERAGE(A1:A200) -> 14.749365 | J23: =AVERAGE(A1:A300) -> 15.233643 | AD23: 4.605 | AE23: 9.218 | AF23: 8.356 | AG23: 7.548 | AH23: 4.927 | AI23: 5.52 | AJ23: 5.226 | AK23: 5.172 | AL23: 9.046 | AM23: 4.612
A24: 7.548 | D24: % | E24: =(E23 - $J23)/ $J23 * 100 -> -20.16355 | F24: =(F23 - $J23)/ $J23 * 100 -> -17.387786 | G24: =(G23 - $J23)/ $J23 * 100 -> -8.3808141 | H24: =(H23 - $J23)/ $J23 * 100 -> 9.8291435 | I24: =(I23 - $J23)/ $J23 * 100 -> -3.1790053 | AD24: 9.218 | AE24: 8.356 | AF24: 7.548 | AG24: 4.927 | AH24: 5.52 | AI24: 5.226 | AJ24: 5.172 | AK24: 9.046 | AL24: 4.612 | AM24: 6.928
A25: 4.927 | C25: Дов. инт. (0,9) | D25: Знач, | E25: =CONFIDENCE(0.1,E33, E22) -> 8.7714329 | F25: =CONFIDENCE(0.1,F33, F22) -> 6.0801106 | G25: =CONFIDENCE(0.1,G33, G22) -> 4.67065 | H25: =CONFIDENCE(0.1,H33, H22) -> 5.185484 | I25: =CONFIDENCE(0.1,I33, I22) -> 3.0126719 | J25: =CONFIDENCE(0.1, J33, J22) -> 2.6293785 | AD25: 8.356 | AE25: 7.548 | AF25: 4.927 | AG25: 5.52 | AH25: 5.226 | AI25: 5.172 | AJ25: 9.046 | AK25: 4.612 | AL25: 6.928 | AM25: 5.446
A26: 5.52 | D26: % | E26: =(E25 - $J25)/ $J25 * 100 -> 233.59339 | F26: =(F25 - $J25)/ $J25 * 100 -> 131.23756 | G26: =(G25 - $J25)/ $J25 * 100 -> 77.633229 | H26: =(H25 - $J25)/ $J25 * 100 -> 97.213292 | I26: =(I25 - $J25)/ $J25 * 100 -> 14.577339 | AD26: 7.548 | AE26: 4.927 | AF26: 5.52 | AG26: 5.226 | AH26: 5.172 | AI26: 9.046 | AJ26: 4.612 | AK26: 6.928 | AL26: 5.446 | AM26: 9.727
A27: 5.226 | C27: Дов. инт. (0,95) | D27: Знач, | E27: =CONFIDENCE(0.05, E33, E22) -> 10.451807 | F27: =CONFIDENCE(0.05, F33, F22) -> 7.2448987 | G27: =CONFIDENCE(0.05, G33, G22) -> 5.5654227 | H27: =CONFIDENCE(0.05, H33, H22) -> 6.1788853 | I27: =CONFIDENCE(0.05, I33, I22) -> 3.58982 | J27: =CONFIDENCE(0.05, J33, J22) -> 3.1330978 | AD27: 4.927 | AE27: 5.52 | AF27: 5.226 | AG27: 5.172 | AH27: 9.046 | AI27: 4.612 | AJ27: 6.928 | AK27: 5.446 | AL27: 9.727 | AM27: 107.898
A28: 5.172 | D28: % | E28: =(E27 - $J27)/ $J27 * 100 -> 233.59339 | F28: =(F27 - $J27)/ $J27 * 100 -> 131.23756 | G28: =(G27 - $J27)/ $J27 * 100 -> 77.633229 | H28: =(H27 - $J27)/ $J27 * 100 -> 97.213292 | I28: =(I27 - $J27)/ $J27 * 100 -> 14.577339 | AD28: 5.52 | AE28: 5.226 | AF28: 5.172 | AG28: 9.046 | AH28: 4.612 | AI28: 6.928 | AJ28: 5.446 | AK28: 9.727 | AL28: 107.898 | AM28: 7.143
A29: 9.046 | C29: Дов. инт. (0,99) | D29: Знач, | E29: =CONFIDENCE(0.01, E33, E22) -> 13.736003 | F29: =CONFIDENCE(0.01, F33, F22) -> 9.5214108 | G29: =CONFIDENCE(0.01, G33, G22) -> 7.3142053 | H29: =CONFIDENCE(0.01, H33, H22) -> 8.1204317 | I29: =CONFIDENCE(0.01, I33, I22) -> 4.7178233 | J29: =CONFIDENCE(0.01, J33, J22) -> 4.1175884 | AD29: 5.226 | AE29: 5.172 | AF29: 9.046 | AG29: 4.612 | AH29: 6.928 | AI29: 5.446 | AJ29: 9.727 | AK29: 107.898 | AL29: 7.143 | AM29: 4.678
A30: 4.612 | D30: % | E30: =(E29 - $J29)/ $J29 * 100 -> 233.59339 | F30: =(F29 - $J29)/ $J29 * 100 -> 131.23756 | G30: =(G29 - $J29)/ $J29 * 100 -> 77.633229 | H30: =(H29 - $J29)/ $J29 * 100 -> 97.213292 | I30: =(I29 - $J29)/ $J29 * 100 -> 14.577339 | AD30: 5.172 | AE30: 9.046 | AF30: 4.612 | AG30: 6.928 | AH30: 5.446 | AI30: 9.727 | AJ30: 107.898 | AK30: 7.143 | AL30: 4.678 | AM30: 5.083
A31: 6.928 | C31: Дисперсия | D31: Знач, | E31: =_xlfn.VAR.S(A1:A10) -> 284.37184 | F31: =_xlfn.VAR.S(A1:A20) -> 273.27408 | G31: =_xlfn.VAR.S(A1:A50) -> 403.15322 | H31: =_xlfn.VAR.S(A1:A100) -> 993.85741 | I31: =_xlfn.VAR.S(A1:A200) -> 670.93303 | J31: =_xlfn.VAR.S(A1:A300) -> 766.60733 | AD31: 9.046 | AE31: 4.612 | AF31: 6.928 | AG31: 5.446 | AH31: 9.727 | AI31: 107.898 | AJ31: 7.143 | AK31: 4.678 | AL31: 5.083 | AM31: 4.617
A32: 5.446 | D32: % | E32: =(E31 - $J31)/ $J31 * 100 -> -62.905151 | F32: =(F31 - $J31)/ $J31 * 100 -> -64.352795 | G32: =(G31 - $J31)/ $J31 * 100 -> -47.410727 | H32: =(H31 - $J31)/ $J31 * 100 -> 29.643609 | I32: =(I31 - $J31)/ $J31 * 100 -> -12.480223 | AD32: 4.612 | AE32: 6.928 | AF32: 5.446 | AG32: 9.727 | AH32: 107.898 | AI32: 7.143 | AJ32: 4.678 | AK32: 5.083 | AL32: 4.617 | AM32: 6.357
A33: 9.727 | C33: С. к. о. | D33: Знач, | E33: =STDEV(A1:A10) -> 16.863328 | F33: =STDEV(A1:A20) -> 16.531004 | G33: =STDEV(A1:A50) -> 20.078676 | H33: =STDEV(A1:A100) -> 31.525504 | I33: =STDEV(A1:A200) -> 25.902375 | J33: =STDEV(A1:A300) -> 27.687675 | AD33: 6.928 | AE33: 5.446 | AF33: 9.727 | AG33: 107.898 | AH33: 7.143 | AI33: 4.678 | AJ33: 5.083 | AK33: 4.617 | AL33: 6.357 | AM33: 35.72
A34: 107.898 | D34: % | E34: =(E33 - $J33)/ $J33 * 100 -> -39.094459 | F34: =(F33 - $J33)/ $J33 * 100 -> -40.29472 | G34: =(G33 - $J33)/ $J33 * 100 -> -27.481538 | H34: =(H33 - $J33)/ $J33 * 100 -> 13.861147 | I34: =(I33 - $J33)/ $J33 * 100 -> -6.4479948 | AD34: 5.446 | AE34: 9.727 | AF34: 107.898 | AG34: 7.143 | AH34: 4.678 | AI34: 5.083 | AJ34: 4.617 | AK34: 6.357 | AL34: 35.72 | AM34: 44.366
A35: 7.143 | C35: К-т вариации | D35: Знач, | E35: =E33/E23 -> 1.3865588 | F35: =F33/F23 -> 1.3135638 | G35: =G33/G23 -> 1.4386159 | H35: =H33/H23 -> 1.8842593 | I35: =I33/I23 -> 1.7561688 | J35: =J33/J23 -> 1.8175347 | AD35: 9.727 | AE35: 107.898 | AF35: 7.143 | AG35: 4.678 | AH35: 5.083 | AI35: 4.617 | AJ35: 6.357 | AK35: 35.72 | AL35: 44.366 | AM35: 30.174
A36: 4.678 | D36: % | E36: =(E35 - $J35)/ $J35 * 100 -> -23.712112 | F36: =(F35 - $J35)/ $J35 * 100 -> -27.728265 | G36: =(G35 - $J35)/ $J35 * 100 -> -20.847952 | H36: =(H35 - $J35)/ $J35 * 100 -> 3.6711602 | I36: =(I35 - $J35)/ $J35 * 100 -> -3.3763229 | AD36: 107.898 | AE36: 7.143 | AF36: 4.678 | AG36: 5.083 | AH36: 4.617 | AI36: 6.357 | AJ36: 35.72 | AK36: 44.366 | AL36: 30.174 | AM36: 5.299
A37: 5.083 | AD37: 7.143 | AE37: 4.678 | AF37: 5.083 | AG37: 4.617 | AH37: 6.357 | AI37: 35.72 | AJ37: 44.366 | AK37: 30.174 | AL37: 5.299 | AM37: 4.663
A38: 4.617 | AD38: 4.678 | AE38: 5.083 | AF38: 4.617 | AG38: 6.357 | AH38: 35.72 | AI38: 44.366 | AJ38: 30.174 | AK38: 5.299 | AL38: 4.663 | AM38: 9.753
A39: 6.357 | AD39: 5.083 | AE39: 4.617 | AF39: 6.357 | AG39: 35.72 | AH39: 44.366 | AI39: 30.174 | AJ39: 5.299 | AK39: 4.663 | AL39: 9.753 | AM39: 6.803
A40: 35.72 | C40: . | D40: Закон распределения: Гиперэкспоненциальное закон | AD40: 4.617 | AE40: 6.357 | AF40: 35.72 | AG40: 44.366 | AH40: 30.174 | AI40: 5.299 | AJ40: 4.663 | AK40: 9.753 | AL40: 6.803 | AM40: 7.795
A41: 44.366 | C41: . | AD41: 6.357 | AE41: 35.72 | AF41: 44.366 | AG41: 30.174 | AH41: 5.299 | AI41: 4.663 | AJ41: 9.753 | AK41: 6.803 | AL41: 7.795 | AM41: 4.951
A42: 30.174 | C42: . | AD42: 35.72 | AE42: 44.366 | AF42: 30.174 | AG42: 5.299 | AH42: 4.663 | AI42: 9.753 | AJ42: 6.803 | AK42: 7.795 | AL42: 4.951 | AM42: 9.808
A43: 5.299 | AD43: 44.366 | AE43: 30.174 | AF43: 5.299 | AG43: 4.663 | AH43: 9.753 | AI43: 6.803 | AJ43: 7.795 | AK43: 4.951 | AL43: 9.808 | AM43: 64.711
A44: 4.663 | AD44: 30.174 | AE44: 5.299 | AF44: 4.663 | AG44: 9.753 | AH44: 6.803 | AI44: 7.795 | AJ44: 4.951 | AK44: 9.808 | AL44: 64.711 | AM44: 7.347
...

Sheet Лист2
A1: 4.684964 | AC1: Сдвиг ЧП | AD1: 1 | AE1: 2 | AF1: 3 | AG1: 4 | AH1: 5 | AI1: 6 | AJ1: 7 | AK1: 8 | AL1: 9 | AM1: 10
A2: 0.04302319 | AC2: К-т АК | AD2: =COVAR($A1:$A300,AD4:AD303)/SQRT(VAR($A1:$A300)*VAR(AD4:AD303)) -> 0.044795478 | AE2: =COVAR($A1:$A300,AE4:AE303)/SQRT(VAR($A1:$A300)*VAR(AE4:AE303)) -> -0.026511802 | AF2: =COVAR($A1:$A300,AF4:AF303)/SQRT(VAR($A1:$A300)*VAR(AF4:AF303)) -> 0.082055311 | AG2: =COVAR($A1:$A300,AG4:AG303)/SQRT(VAR($A1:$A300)*VAR(AG4:AG303)) -> 0.13916812 | AH2: =COVAR($A1:$A300,AH4:AH303)/SQRT(VAR($A1:$A300)*VAR(AH4:AH303)) -> 0.011409787 | AI2: =COVAR($A1:$A300,AI4:AI303)/SQRT(VAR($A1:$A300)*VAR(AI4:AI303)) -> -0.051629124 | AJ2: =COVAR($A1:$A300,AJ4:AJ303)/SQRT(VAR($A1:$A300)*VAR(AJ4:AJ303)) -> -0.084476838 | AK2: =COVAR($A1:$A300,AK4:AK303)/SQRT(VAR($A1:$A300)*VAR(AK4:AK303)) -> -0.06471071 | ... AM2: =COVAR($A1:$A300,AM4:AM303)/SQRT(VAR($A1:$A300)*VAR(AM4:AM303)) -> -0.060353986
A3: 3.4345014
A4: 1.1980629 | AD4: 0.04302319 | AE4: =$A3 -> 3.4345014 | AF4: =$A4 -> 1.1980629 | AG4: =$A5 -> 19.197822 | AH4: =$A6 -> 13.412696 | AI4: =$A7 -> 44.728837 | AJ4: =$A8 -> 2.6450552 | AK4: =$A9 -> 3.4821343 | AL4: =$A10 -> 0.7465676 | AM4: =$A11 -> 0.9029075
A5: 19.197822 | AD5: 3.4345014 | AE5: =$A4 -> 1.1980629 | AF5: =$A5 -> 19.197822 | AG5: =$A6 -> 13.412696 | AH5: =$A7 -> 44.728837 | AI5: =$A8 -> 2.6450552 | AJ5: =$A9 -> 3.4821343 | AK5: =$A10 -> 0.7465676 | AL5: =$A11 -> 0.9029075 | AM5: =$A12 -> 0.24115809
A6: 13.412696 | AD6: 1.1980629 | AE6: =$A5 -> 19.197822 | AF6: =$A6 -> 13.412696 | AG6: =$A7 -> 44.728837 | AH6: =$A8 -> 2.6450552 | AI6: =$A9 -> 3.4821343 | AJ6: =$A10 -> 0.7465676 | AK6: =$A11 -> 0.9029075 | AL6: =$A12 -> 0.24115809 | AM6: =$A13 -> 2.2651086
A7: 44.728837 | AD7: 19.197822 | AE7: =$A6 -> 13.412696 | AF7: =$A7 -> 44.728837 | AG7: =$A8 -> 2.6450552 | AH7: =$A9 -> 3.4821343 | AI7: =$A10 -> 0.7465676 | AJ7: =$A11 -> 0.9029075 | AK7: =$A12 -> 0.24115809 | AL7: =$A13 -> 2.2651086 | AM7: =$A14 -> 3.0694652
A8: 2.6450552 | AD8: 13.412696 | AE8: =$A7 -> 44.728837 | AF8: =$A8 -> 2.6450552 | AG8: =$A9 -> 3.4821343 | AH8: =$A10 -> 0.7465676 | AI8: =$A11 -> 0.9029075 | AJ8: =$A12 -> 0.24115809 | AK8: =$A13 -> 2.2651086 | AL8: =$A14 -> 3.0694652 | AM8: =$A15 -> 0.72086474
A9: 3.4821343 | AD9: 44.728837 | AE9: =$A8 -> 2.6450552 | AF9: =$A9 -> 3.4821343 | AG9: =$A10 -> 0.7465676 | AH9: =$A11 -> 0.9029075 | AI9: =$A12 -> 0.24115809 | AJ9: =$A13 -> 2.2651086 | AK9: =$A14 -> 3.0694652 | AL9: =$A15 -> 0.72086474 | AM9: =$A16 -> 1.6246155
A10: 0.7465676 | AD10: 2.6450552 | AE10: =$A9 -> 3.4821343 | AF10: =$A10 -> 0.7465676 | AG10: =$A11 -> 0.9029075 | AH10: =$A12 -> 0.24115809 | AI10: =$A13 -> 2.2651086 | AJ10: =$A14 -> 3.0694652 | AK10: =$A15 -> 0.72086474 | AL10: =$A16 -> 1.6246155 | AM10: =$A17 -> 3.0990788
A11: 0.9029075 | AD11: 3.4821343 | AE11: =$A10 -> 0.7465676 | AF11: =$A11 -> 0.9029075 | AG11: =$A12 -> 0.24115809 | AH11: =$A13 -> 2.2651086 | AI11: =$A14 -> 3.0694652 | AJ11: =$A15 -> 0.72086474 | AK11: =$A16 -> 1.6246155 | AL11: =$A17 -> 3.0990788 | AM11: =$A18 -> 3.3035633
A12: 0.24115809 | AD12: 0.7465676 | AE12: =$A11 -> 0.9029075 | AF12: =$A12 -> 0.24115809 | AG12: =$A13 -> 2.2651086 | AH12: =$A14 -> 3.0694652 | AI12: =$A15 -> 0.72086474 | AJ12: =$A16 -> 1.6246155 | AK12: =$A17 -> 3.0990788 | AL12: =$A18 -> 3.3035633 | AM12: =$A19 -> 0.99493259
A13: 2.2651086 | AD13: 0.9029075 | AE13: =$A12 -> 0.24115809 | AF13: =$A13 -> 2.2651086 | AG13: =$A14 -> 3.0694652 | AH13: =$A15 -> 0.72086474 | AI13: =$A16 -> 1.6246155 | AJ13: =$A17 -> 3.0990788 | AK13: =$A18 -> 3.3035633 | AL13: =$A19 -> 0.99493259 | AM13: =$A20 -> 0.0036606518
A14: 3.0694652 | AD14: 0.24115809 | AE14: =$A13 -> 2.2651086 | AF14: =$A14 -> 3.0694652 | AG14: =$A15 -> 0.72086474 | AH14: =$A16 -> 1.6246155 | AI14: =$A17 -> 3.0990788 | AJ14: =$A18 -> 3.3035633 | AK14: =$A19 -> 0.99493259 | AL14: =$A20 -> 0.0036606518 | AM14: =$A21 -> 14.860598
A15: 0.72086474 | AD15: 2.2651086 | AE15: =$A14 -> 3.0694652 | AF15: =$A15 -> 0.72086474 | AG15: =$A16 -> 1.6246155 | AH15: =$A17 -> 3.0990788 | AI15: =$A18 -> 3.3035633 | AJ15: =$A19 -> 0.99493259 | AK15: =$A20 -> 0.0036606518 | AL15: =$A21 -> 14.860598 | AM15: =$A22 -> 3.0204494
... A20: 0.0036606518 | AD20: 3.3035633 | AE20: =$A19 -> 0.99493259 | AF20: =$A20 -> 0.0036606518 | AG20: =$A21 -> 14.860598 | AH20: =$A22 -> 3.0204494 | AI20: =$A23 -> 0.87024585 | AJ20: =$A24 -> 0.88341314 | AK20: =$A25 -> 6.5755809 | AL20: =$A26 -> 4.0006412 | AM20: =$A27 -> 2.8929408
A21: 14.860598 | C21: Характеристика | E21: Количество случайных величин | AD21: 0.99493259 | AE21: =$A20 -> 0.0036606518 | AF21: =$A21 -> 14.860598 | AG21: =$A22 -> 3.0204494 | AH21: =$A23 -> 0.87024585 | AI21: =$A24 -> 0.88341314 | AJ21: =$A25 -> 6.5755809 | AK21: =$A26 -> 4.0006412 | AL21: =$A27 -> 2.8929408 | AM21: =$A28 -> 0.45716243
A22: 3.0204494 | E22: 10 | F22: 20 | G22: 50 | H22: 100 | I22: 200 | J22: 300 | AD22: 0.0036606518 | AE22: =$A21 -> 14.860598 | AF22: =$A22 -> 3.0204494 | AG22: =$A23 -> 0.87024585 | AH22: =$A24 -> 0.88341314 | AI22: =$A25 -> 6.5755809 | AJ22: =$A26 -> 4.0006412 | AK22: =$A27 -> 2.8929408 | AL22: =$A28 -> 0.45716243 | AM22: =$A29 -> 1.2064285
A23: 0.87024585 | C23: Мат. ож. | D23: Знач, | E23: =AVERAGE(A1:A10) -> 9.3573664 | F23: =AVERAGE(A1:A20) -> 5.4899509 | G23: =AVERAGE(A1:A50) -> 8.2877747 | H23: =AVERAGE(A1:A100) -> 8.9784111 | I23: =AVERAGE(A1:A200) -> 9.3859799 | J23: =AVERAGE(A1:A300) -> 10.820592 | AD23: 14.860598 | AE23: =$A22 -> 3.0204494 | AF23: =$A23 -> 0.87024585 | AG23: =$A24 -> 0.88341314 | AH23: =$A25 -> 6.5755809 | AI23: =$A26 -> 4.0006412 | AJ23: =$A27 -> 2.8929408 | AK23: =$A28 -> 0.45716243 | AL23: =$A29 -> 1.2064285 | AM23: =$A30 -> 3.1864571
A24: 0.88341314 | D24: % | E24: =(E23 - Лист1!$J23)/ Лист1!$J23 * 100 -> -38.574337 | F24: =(F23 - Лист1!$J23)/ Лист1!$J23 * 100 -> -63.961668 | G24: =(G23 - Лист1!$J23)/ Лист1!$J23 * 100 -> -45.595584 | H24: =(H23 - Лист1!$J23)/ Лист1!$J23 * 100 -> -41.061958 | I24: =(I23 - Лист1!$J23)/ Лист1!$J23 * 100 -> -38.386506 | J24: =(J23 - Лист1!$J23)/ Лист1!$J23 * 100 -> -28.969113 | AD24: 3.0204494 | AE24: =$A23 -> 0.87024585 | AF24: =$A24 -> 0.88341314 | AG24: =$A25 -> 6.5755809 | AH24: =$A26 -> 4.0006412 | AI24: =$A27 -> 2.8929408 | AJ24: =$A28 -> 0.45716243 | AK24: =$A29 -> 1.2064285 | AL24: =$A30 -> 3.1864571 | AM24: =$A31 -> 66.1876
A25: 6.5755809 | C25: Дов. инт. (0,9) | D25: Знач, | E25: =CONFIDENCE(0.1,E33, E22) -> 7.208187 | F25: =CONFIDENCE(0.1,F33, F22) -> 3.8123044 | G25: =CONFIDENCE(0.1,G33, G22) -> 4.1282133 | H25: =CONFIDENCE(0.1,H33, H22) -> 4.3697916 | I25: =CONFIDENCE(0.1,I33, I22) -> 2.8949256 | J25: =CONFIDENCE(0.1, J33, J22) -> 2.5566865 | AD25: 0.87024585 | AE25: =$A24 -> 0.88341314 | AF25: =$A25 -> 6.5755809 | AG25: =$A26 -> 4.0006412 | AH25: =$A27 -> 2.8929408 | AI25: =$A28 -> 0.45716243 | AJ25: =$A29 -> 1.2064285 | AK25: =$A30 -> 3.1864571 | AL25: =$A31 -> 66.1876 | AM25: =$A32 -> 1.0577756
A26: 4.0006412 | D26: % | E26: =(E25 - Лист1!$J25)/ Лист1!$J25 * 100 -> 174.14033 | F26: =(F25 - Лист1!$J25)/ Лист1!$J25 * 100 -> 44.988801 | G26: =(G25 - Лист1!$J25)/ Лист1!$J25 * 100 -> 57.003385 | H26: =(H25 - Лист1!$J25)/ Лист1!$J25 * 100 -> 66.191043 | I26: =(I25 - Лист1!$J25)/ Лист1!$J25 * 100 -> 10.099232 | J26: =(J25 - Лист1!$J25)/ Лист1!$J25 * 100 -> -2.7646105 | AD26: 0.88341314 | AE26: =$A25 -> 6.5755809 | AF26: =$A26 -> 4.0006412 | AG26: =$A27 -> 2.8929408 | AH26: =$A28 -> 0.45716243 | AI26: =$A29 -> 1.2064285 | AJ26: =$A30 -> 3.1864571 | AK26: =$A31 -> 66.1876 | AL26: =$A32 -> 1.0577756 | AM26: =$A33 -> 1.9484039
A27: 2.8929408 | C27: Дов. инт. (0,95) | D27: Знач, | E27: =CONFIDENCE(0.05, E33, E22) -> 8.5890846 | F27: =CONFIDENCE(0.05, F33, F22) -> 4.5426409 | G27: =CONFIDENCE(0.05, G33, G22) -> 4.9190696 | H27: =CONFIDENCE(0.05, H33, H22) -> 5.2069279 | I27: =CONFIDENCE(0.05, I33, I22) -> 3.4495166 | J27: =CONFIDENCE(0.05, J33, J22) -> 3.0464798 | AD27: 6.5755809 | AE27: =$A26 -> 4.0006412 | AF27: =$A27 -> 2.8929408 | AG27: =$A28 -> 0.45716243 | AH27: =$A29 -> 1.2064285 | AI27: =$A30 -> 3.1864571 | AJ27: =$A31 -> 66.1876 | AK27: =$A32 -> 1.0577756 | AL27: =$A33 -> 1.9484039 | AM27: =$A34 -> 51.092621
A28: 0.45716243 | D28: % | E28: =(E27 - Лист1!$J27)/ Лист1!$J27 * 100 -> 174.14033 | F28: =(F27 - Лист1!$J27)/ Лист1!$J27 * 100 -> 44.988801 | G28: =(G27 - Лист1!$J27)/ Лист1!$J27 * 100 -> 57.003385 | H28: =(H27 - Лист1!$J27)/ Лист1!$J27 * 100 -> 66.191043 | I28: =(I27 - Лист1!$J27)/ Лист1!$J27 * 100 -> 10.099232 | J28: =(J27 - Лист1!$J27)/ Лист1!$J27 * 100 -> -2.7646105 | AD28: 4.0006412 | AE28: =$A27 -> 2.8929408 | AF28: =$A28 -> 0.45716243 | AG28: =$A29 -> 1.2064285 | AH28: =$A30 -> 3.1864571 | AI28: =$A31 -> 66.1876 | AJ28: =$A32 -> 1.0577756 | AK28: =$A33 -> 1.9484039 | AL28: =$A34 -> 51.092621 | AM28: =$A35 -> 92.754994
A29: 1.2064285 | C29: Дов. инт. (0,99) | D29: Знач, | E29: =CONFIDENCE(0.01, E33, E22) -> 11.287971 | F29: =CONFIDENCE(0.01, F33, F22) -> 5.9700421 | G29: =CONFIDENCE(0.01, G33, G22) -> 6.4647532 | H29: =CONFIDENCE(0.01, H33, H22) -> 6.8430632 | I29: =CONFIDENCE(0.01, I33, I22) -> 4.5334332 | J29: =CONFIDENCE(0.01, J33, J22) -> 4.0037532 | AD29: 2.8929408 | AE29: =$A28 -> 0.45716243 | AF29: =$A29 -> 1.2064285 | AG29: =$A30 -> 3.1864571 | AH29: =$A31 -> 66.1876 | AI29: =$A32 -> 1.0577756 | AJ29: =$A33 -> 1.9484039 | AK29: =$A34 -> 51.092621 | AL29: =$A35 -> 92.754994 | AM29: =$A36 -> 6.6289891
A30: 3.1864571 | D30: % | E30: =(E29 - Лист1!$J29)/ Лист1!$J29 * 100 -> 174.14033 | F30: =(F29 - Лист1!$J29)/ Лист1!$J29 * 100 -> 44.988801 | G30: =(G29 - Лист1!$J29)/ Лист1!$J29 * 100 -> 57.003385 | H30: =(H29 - Лист1!$J29)/ Лист1!$J29 * 100 -> 66.191043 | I30: =(I29 - Лист1!$J29)/ Лист1!$J29 * 100 -> 10.099232 | J30: =(J29 - Лист1!$J29)/ Лист1!$J29 * 100 -> -2.7646105 | AD30: 0.45716243 | AE30: =$A29 -> 1.2064285 | AF30: =$A30 -> 3.1864571 | AG30: =$A31 -> 66.1876 | AH30: =$A32 -> 1.0577756 | AI30: =$A33 -> 1.9484039 | AJ30: =$A34 -> 51.092621 | AK30: =$A35 -> 92.754994 | AL30: =$A36 -> 6.6289891 | AM30: =$A37 -> 0.89626636
A31: 66.1876 | C31: Дисперсия | D31: Знач, | E31: =_xlfn.VAR.S(A1:A10) -> 192.0426 | F31: =_xlfn.VAR.S(A1:A20) -> 107.4362 | G31: =_xlfn.VAR.S(A1:A50) -> 314.94865 | H31: =_xlfn.VAR.S(A1:A100) -> 705.77609 | I31: =_xlfn.VAR.S(A1:A200) -> 619.5128 | J31: =_xlfn.VAR.S(A1:A300) -> 724.80584 | AD31: 1.2064285 | AE31: =$A30 -> 3.1864571 | AF31: =$A31 -> 66.1876 | AG31: =$A32 -> 1.0577756 | AH31: =$A33 -> 1.9484039 | AI31: =$A34 -> 51.092621 | AJ31: =$A35 -> 92.754994 | AK31: =$A36 -> 6.6289891 | AL31: =$A37 -> 0.89626636 | AM31: =$A38 -> 4.3942719
A32: 1.0577756 | D32: % | E32: =(E31 - Лист1!$J31)/ Лист1!$J31 * 100 -> -74.949026 | F32: =(F31 - Лист1!$J31)/ Лист1!$J31 * 100 -> -85.985498 | G32: =(G31 - Лист1!$J31)/ Лист1!$J31 * 100 -> -58.916562 | H32: =(H31 - Лист1!$J31)/ Лист1!$J31 * 100 -> -7.9351242 | I32: =(I31 - Лист1!$J31)/ Лист1!$J31 * 100 -> -19.187728 | J32: =(J31 - Лист1!$J31)/ Лист1!$J31 * 100 -> -5.4527903 | AD32: 3.1864571 | AE32: =$A31 -> 66.1876 | AF32: =$A32 -> 1.0577756 | AG32: =$A33 -> 1.9484039 | AH32: =$A34 -> 51.092621 | AI32: =$A35 -> 92.754994 | AJ32: =$A36 -> 6.6289891 | AK32: =$A37 -> 0.89626636 | AL32: =$A38 -> 4.3942719 | AM32: =$A39 -> 2.5736218
A33: 1.9484039 | C33: С. к. о. | D33: Знач, | E33: =STDEV(A1:A10) -> 13.857944 | F33: =STDEV(A1:A20) -> 10.365143 | G33: =STDEV(A1:A50) -> 17.746793 | H33: =STDEV(A1:A100) -> 26.566447 | I33: =STDEV(A1:A200) -> 24.890014 | J33: =STDEV(A1:A300) -> 26.922218 | AD33: 66.1876 | AE33: =$A32 -> 1.0577756 | AF33: =$A33 -> 1.9484039 | AG33: =$A34 -> 51.092621 | AH33: =$A35 -> 92.754994 | AI33: =$A36 -> 6.6289891 | AJ33: =$A37 -> 0.89626636 | AK33: =$A38 -> 4.3942719 | AL33: =$A39 -> 2.5736218 | AM33: =$A40 -> 9.8449746
A34: 51.092621 | D34: % | E34: =(E33 - Лист1!$J33)/ Лист1!$J33 * 100 -> -49.949052 | F34: =(F33 - Лист1!$J33)/ Лист1!$J33 * 100 -> -62.564053 | G34: =(G33 - Лист1!$J33)/ Лист1!$J33 * 100 -> -35.903637 | H34: =(H33 - Лист1!$J33)/ Лист1!$J33 * 100 -> -4.0495566 | I34: =(I33 - Лист1!$J33)/ Лист1!$J33 * 100 -> -10.104354 | J34: =(J33 - Лист1!$J33)/ Лист1!$J33 * 100 -> -2.7646105 | AD34: 1.0577756 | AE34: =$A33 -> 1.9484039 | AF34: =$A34 -> 51.092621 | AG34: =$A35 -> 92.754994 | AH34: =$A36 -> 6.6289891 | AI34: =$A37 -> 0.89626636 | AJ34: =$A38 -> 4.3942719 | AK34: =$A39 -> 2.5736218 | AL34: =$A40 -> 9.8449746 | AM34: =$A41 -> 5.0437027
A35: 92.754994 | C35: К-т вариации | D35: Знач, | E35: =E33/E23 -> 1.4809662 | F35: =F33/F23 -> 1.8880211 | G35: =G33/G23 -> 2.1413218 | H35: =H33/H23 -> 2.9589252 | I35: =I33/I23 -> 2.6518291 | J35: =J33/J23 -> 2.4880541 | AD35: 1.9484039 | AE35: =$A34 -> 51.092621 | AF35: =$A35 -> 92.754994 | AG35: =$A36 -> 6.6289891 | AH35: =$A37 -> 0.89626636 | AI35: =$A38 -> 4.3942719 | AJ35: =$A39 -> 2.5736218 | AK35: =$A40 -> 9.8449746 | AL35: =$A41 -> 5.0437027 | AM35: =$A42 -> 2.2583604
A36: 6.6289891 | D36: % | E36: =(E35 - Лист1!$J35)/ Лист1!$J35 * 100 -> -18.517855 | F36: =(F35 - Лист1!$J35)/ Лист1!$J35 * 100 -> 3.8781358 | G36: =(G35 - Лист1!$J35)/ Лист1!$J35 * 100 -> 17.814634 | H36: =(H35 - Лист1!$J35)/ Лист1!$J35 * 100 -> 62.798831 | I36: =(I35 - Лист1!$J35)/ Лист1!$J35 * 100 -> 45.902531 | J36: =(J35 - Лист1!$J35)/ Лист1!$J35 * 100 -> 36.891701 | AD36: 51.092621 | AE36: =$A35 -> 92.754994 | AF36: =$A36 -> 6.6289891 | AG36: =$A37 -> 0.89626636 | AH36: =$A38 -> 4.3942719 | AI36: =$A39 -> 2.5736218 | AJ36: =$A40 -> 9.8449746 | AK36: =$A41 -> 5.0437027 | AL36: =$A42 -> 2.2583604 | AM36: =$A43 -> 6.6037519
A37: 0.89626636 | AD37: 92.754994 | AE37: =$A36 -> 6.6289891 | AF37: =$A37 -> 0.89626636 | AG37: =$A38 -> 4.3942719 | AH37: =$A39 -> 2.5736218 | AI37: =$A40 -> 9.8449746 | AJ37: =$A41 -> 5.0437027 | AK37: =$A42 -> 2.2583604 | AL37: =$A43 -> 6.6037519 | AM37: =$A44 -> 1.5613254
A38: 4.3942719 | AD38: 6.6289891 | AE38: =$A37 -> 0.89626636 | AF38: =$A38 -> 4.3942719 | AG38: =$A39 -> 2.5736218 | AH38: =$A40 -> 9.8449746 | AI38: =$A41 -> 5.0437027 | AJ38: =$A42 -> 2.2583604 | AK38: =$A43 -> 6.6037519 | AL38: =$A44 -> 1.5613254 | AM38: =$A45 -> 2.6819169
A39: 2.5736218 | AD39: 0.89626636 | AE39: =$A38 -> 4.3942719 | AF39: =$A39 -> 2.5736218 | AG39: =$A40 -> 9.8449746 | AH39: =$A41 -> 5.0437027 | AI39: =$A42 -> 2.2583604 | AJ39: =$A43 -> 6.6037519 | AK39: =$A44 -> 1.5613254 | AL39: =$A45 -> 2.6819169 | AM39: =$A46 -> 7.3567786
A40: 9.8449746 | AD40: 4.3942719 | AE40: =$A39 -> 2.5736218 | AF40: =$A40 -> 9.8449746 | AG40: =$A41 -> 5.0437027 | AH40: =$A42 -> 2.2583604 | AI40: =$A43 -> 6.6037519 | AJ40: =$A44 -> 1.5613254 | AK40: =$A45 -> 2.6819169 | AL40: =$A46 -> 7.3567786 | AM40: =$A47 -> 2.4154846
A41: 5.0437027 | AD41: 2.5736218 | AE41: =$A40 -> 9.8449746 | AF41: =$A41 -> 5.0437027 | AG41: =$A42 -> 2.2583604 | AH41: =$A43 -> 6.6037519 | AI41: =$A44 -> 1.5613254 | AJ41: =$A45 -> 2.6819169 | AK41: =$A46 -> 7.3567786 | AL41: =$A47 -> 2.4154846 | AM41: =$A48 -> 0.65379475
A42: 2.2583604 | AD42: 9.8449746 | AE42: =$A41 -> 5.0437027 | AF42: =$A42 -> 2.2583604 | AG42: =$A43 -> 6.6037519 | AH42: =$A44 -> 1.5613254 | AI42: =$A45 -> 2.6819169 | AJ42: =$A46 -> 7.3567786 | AK42: =$A47 -> 2.4154846 | AL42: =$A48 -> 0.65379475 | AM42: =$A49 -> 0.041012
A43: 6.6037519 | AD43: 5.0437027 | AE43: =$A42 -> 2.2583604 | AF43: =$A43 -> 6.6037519 | AG43: =$A44 -> 1.5613254 | AH43: =$A45 -> 2.6819169 | AI43: =$A46 -> 7.3567786 | AJ43: =$A47 -> 2.4154846 | AK43: =$A48 -> 0.65379475 | AL43: =$A49 -> 0.041012 | AM43: =$A50 -> 0.64015374
A44: 1.5613254 | AD44: 2.2583604 | AE44: =$A43 -> 6.6037519 | AF44: =$A44 -> 1.5613254 | AG44: =$A45 -> 2.6819169 | AH44: =$A46 -> 7.3567786 | AI44: =$A47 -> 2.4154846 | AJ44: =$A48 -> 0.65379475 | AK44: =$A49 -> 0.041012 | AL44: =$A50 -> 0.64015374 | AM44: =$A51 -> 14.898814
...

Sheet Лист3
A1: 59.861 | B1: 4.684964 | C1: =CORREL(A1:A300, B1:B300) -> -0.0020008862
A2: 9.353 | B2: 0.04302319
A3: 4.713 | B3: 3.4345014
A4: 4.612 | B4: 1.1980629
A5: 6.48 | B5: 19.197822
A6: 7.944 | B6: 13.412696
A7: 5.281 | B7: 44.728837
A8: 5.345 | B8: 2.6450552
A9: 9.208 | B9: 3.4821343
A10: 8.823 | B10: 0.7465676
A11: 4.709 | B11: 0.9029075
A12: 4.723 | B12: 0.24115809
A13: 6.556 | B13: 2.2651086
... A300: 5.813 | B300: 2.2760581
